<?xml version="1.0" ?>
<robot name='robot' xmlns:xacro="http://ros.org/wiki/xacro">

    <xacro:include filename="$(find robot_description)/urdf/gazebo.urdf.xacro" />
    <xacro:include filename="$(find robot_description)/urdf/lidar.urdf.xacro" />
    <xacro:include filename="$(find robot_description)/urdf/depth.urdf.xacro" />

    <xacro:property name="M_PI" value="3.1415926535897931" />

    <xacro:property name="chassis_length" value="0.176"/>
    <xacro:property name="chassis_width" value="0.13"/>
    <xacro:property name="chassis_height" value="0.069"/>
    <xacro:property name="wheel_radius" value="0.033"/>
    <xacro:property name="wheel_thickness" value="0.018"/>
    <xacro:property name="wheel_mass" value="0.2"/>
    <xacro:property name="wheel_offset_x" value="0.0375"/>
    <xacro:property name="wheel_offset_y" value="0.055"/>
    <xacro:property name="wheel_offset_z" value="0.01"/>
    <xacro:property name="caster_wheel_radius" value="0.024"/>
    <xacro:property name="caster_wheel_mass" value="0.01"/>
    <xacro:property name="caster_wheel_offset_x" value="0.08"/>
    <xacro:property name="caster_wheel_offset_z" value="-0.05"/>
    <xacro:property name="mass" value="1.0"/>

    <material name="white">
        <color rgba="1 1 1 1" />
    </material>

    <material name="orange">
        <color rgba="1 0.3 0.1 1"/>
    </material>

    <material name="blue">
        <color rgba="0.2 0.2 1 1"/>
    </material>

    <material name="black">
        <color rgba="0 0 0 1"/>
    </material>

    <material name="red">
        <color rgba="1 0 0 1"/>
    </material>

    <link name="base_link" />
    <link name="base_footprint" />

    <joint name="base_footprint_joint" type="fixed">
        <parent link="base_link"/>
        <child link="base_footprint"/>
        <origin xyz="0 0 -0.03" rpy="0 0 0"/>
    </joint>

    <joint name="chassis_joint" type="fixed">
        <parent link="base_link"/>
        <child link="chassis"/>
        <origin xyz="0 0 0.04" rpy="0 0 ${M_PI}"/>
    </joint>

    <link name='chassis'>
        <inertial>
            <mass value="${mass}" />
            <inertia ixx="1e-3" ixy="0.0" ixz="0.0"
                     iyy="1e-3" iyz="0.0"
                     izz="1e-3" />
        </inertial>
        <visual>
            <geometry>
                <mesh filename="file://$(find robot_description)/urdf/body_center.stl" scale="0.001 0.001 0.001"/>
            </geometry>
            <material name="blue"/>
        </visual>
        <collision>
            <geometry>
                <box size="${chassis_length} ${chassis_width} ${chassis_height}"/>
            </geometry>
        </collision>
    </link>

    <gazebo reference="chassis">
        <material>Gazebo/Orange</material>
    </gazebo>

    <joint name="left_wheel_joint" type="continuous">
        <parent link="base_link"/>
        <child link="left_wheel"/>
        <origin xyz="${wheel_offset_x} ${wheel_offset_y} 0" rpy="0 0 0" />
        <axis xyz="0 1 0"/>
    </joint>

    <link name="left_wheel">
        <visual>
            <geometry>
                <mesh filename="file://$(find robot_description)/urdf/left_tire.stl" scale="0.001 0.001 0.001"/>
            </geometry>
            <material name="blue"/>
        </visual>
        <collision>
            <geometry>
                <sphere radius="${wheel_radius}"/>
            </geometry>
        </collision>
        <inertial>
            <origin xyz="0 0 0" rpy="0 0 0"/>
            <mass value="2.8498940e-02" />
            <inertia ixx="1.1175580e-05" ixy="-4.2369783e-11" ixz="-5.9381719e-09"
                     iyy="1.1192413e-05" iyz="-1.4400107e-11"
                     izz="2.0712558e-05" />
        </inertial>
    </link>

    <gazebo reference="left_wheel">
        <material>Gazebo/Blue</material>
    </gazebo>

    <joint name="right_wheel_joint" type="continuous">
        <parent link="base_link"/>
        <child link="right_wheel"/>
        <origin xyz="${wheel_offset_x} ${-wheel_offset_y} 0" rpy="0 0 0" />
        <axis xyz="0 1 0"/>
    </joint>

    <link name="right_wheel">
        <visual>
            <geometry>
                <mesh filename="file://$(find robot_description)/urdf/right_tire.stl" scale="0.001 0.001 0.001"/>
            </geometry>
            <material name="blue"/>
        </visual>
        <collision>
            <geometry>
                <sphere radius="${wheel_radius}"/>
            </geometry>
        </collision>
        <inertial>
            <origin xyz="0 0 0" rpy="0 0 0"/>
            <mass value="2.8498940e-02" />
            <inertia ixx="1.1175580e-05" ixy="-4.2369783e-11" ixz="-5.9381719e-09"
                     iyy="1.1192413e-05" iyz="-1.4400107e-11"
                     izz="2.0712558e-05" />
        </inertial>
    </link>

    <gazebo reference="right_wheel">
        <material>Gazebo/Blue</material>
    </gazebo>

    <joint name="caster_wheel_joint" type="fixed">
        <parent link="chassis"/>
        <child link="caster_wheel"/>
        <origin xyz="${caster_wheel_offset_x} 0 ${caster_wheel_offset_z}"/>
    </joint>


    <link name="caster_wheel">
        <visual>
            <geometry>
                <mesh filename="file://$(find robot_description)/urdf/left_tire.stl" scale="0.0009 0.0009 0.0009"/>
            </geometry>
            <material name="white"/>
        </visual>
        <collision>
            <geometry>
                <sphere radius="${caster_wheel_radius}"/>
            </geometry>
        </collision>
        <inertial>
            <origin xyz="0 0 0" rpy="0 0 0"/>
            <mass value="${caster_wheel_mass}" />
            <inertia ixx="${(2/5) * caster_wheel_mass * (caster_wheel_radius*caster_wheel_radius)}" ixy="0.0" ixz="0.0"
                     iyy="${(2/5) * caster_wheel_mass * (caster_wheel_radius*caster_wheel_radius)}" iyz="0.0"
                     izz="${(2/5) * caster_wheel_mass * (caster_wheel_radius*caster_wheel_radius)}" />
        </inertial>
    </link>

    <gazebo reference="caster_wheel">
        <mu1 value="0.001"/>
        <mu2 value="0.001"/>
        <material>Gazebo/White</material>
    </gazebo>

</robot>